<?xml version="1.0" encoding="utf-8"?>
<!-- This URDF was automatically created by SolidWorks to URDF Exporter! Originally created by Stephen Brawner (brawner@gmail.com) 
     Commit Version: 1.6.0-4-g7f85cfe  Build Version: 1.6.7995.38578
     For more information, please see http://wiki.ros.org/sw_urdf_exporter -->
<robot
  name="arm_main.SLDASM">
  <link
    name="Turning_Link">
    <inertial>
      <origin
        xyz="3.31317027662591E-05 -1.8414473396882E-05 -0.0293809512378475"
        rpy="0 0 0" />
      <mass
        value="0.348346114242274" />
      <inertia
        ixx="0.000252227391062675"
        ixy="-4.77655343401811E-08"
        ixz="1.16106427520326E-08"
        iyy="0.000252164100995757"
        iyz="4.3597808094984E-08"
        izz="0.0003901762043136" />
    </inertial>
    <visual>
      <origin
        xyz="0 0 0"
        rpy="0 0 0" />
      <geometry>
        <mesh
          filename="../meshes/Turning_Link.STL" />
      </geometry>
      <material
        name="">
        <color
          rgba="0.749019607843137 0.749019607843137 0.749019607843137 1" />
      </material>
    </visual>
    <collision>
      <origin
        xyz="0 0 0"
        rpy="0 0 0" />
      <geometry>
        <mesh
          filename="../meshes/Turning_Link.STL" />
      </geometry>
    </collision>
  </link>
  <link
    name="Shoulder_Link">
    <inertial>
      <origin
        xyz="-9.9935E-05 0.0090611 -0.029684"
        rpy="0 0 0" />
      <mass
        value="0.46304" />
      <inertia
        ixx="0.00034949"
        ixy="-1.0821E-06"
        ixz="-9.8619E-08"
        iyy="0.00037403"
        iyz="6.3613E-08"
        izz="0.00059779" />
    </inertial>
    <visual>
      <origin
        xyz="0 0 0"
        rpy="0 0 0" />
      <geometry>
        <mesh
          filename="../meshes/Shoulder_Link.STL" />
      </geometry>
      <material
        name="">
        <color
          rgba="0.33725 0.33725 0.74902 1" />
      </material>
    </visual>
    <collision>
      <origin
        xyz="0 0 0"
        rpy="0 0 0" />
      <geometry>
        <mesh
          filename="../meshes/Shoulder_Link.STL" />
      </geometry>
    </collision>
  </link>
  <joint
    name="Shoulder"
    type="revolute">
    <origin
      xyz="0 0.02645 0.065"
      rpy="-1.5708 0 0" />
    <parent
      link="Turning_Link" />
    <child
      link="Shoulder_Link" />
    <axis
      xyz="0 0 1" />
    <limit
      lower="-3.14"
      upper="3.14"
      effort="0"
      velocity="0" />
  </joint>
</robot>